<?xml version="1.0"?>
<robot name="EPSON_LS3_B401S">
  <!-- Configuration of the part called 'Base 0'. -->
  <link name="base_link">
    <visual>
      <geometry>
        <mesh filename="/Mesh/Visual/Base.stl"/>
      </geometry>
      <material name="Custom_Color">
        <color rgba="0.9 0.9 0.9 1.0"/>
      </material>
    </visual>
    <collision>
      <geometry>
        <mesh filename="/Mesh/Visual/Base.stl"/>
      </geometry>
    </collision>
    <inertial>
      <mass value="5.5"/>
      <origin rpy="0.0 0.0 0.0" xyz="0.00000 -0.05875 0.09830"/>
      <inertia ixx="0.0412123399" ixy="0.0" ixz="0.0" iyy="0.0266879532" iyz="0.0" izz="0.0324838669"/>
    </inertial>
  </link>
  <!-- Configuration of the part called 'Joint 1'. -->
  <joint name="joint_1" type="revolute">
    <parent link="base_link"/>
    <child link="link_1"/>
    <origin rpy="0.0 0.0 0.0" xyz="0.0 0.0 0.17310"/>
    <axis xyz="0 0 1"/>
    <limit effort="88.0" lower="-0.6981316805" upper="3.8397243023" velocity="6.28"/>
  </joint>
  <link name="link_1">
    <visual>
      <geometry>
        <mesh filename="/Mesh/Visual/Joint_1.stl"/>
      </geometry>
      <material name="Custom_Color">
        <color rgba="0.9 0.9 0.9 1.0"/>
      </material>
    </visual>
    <collision>
      <geometry>
        <mesh filename="/Mesh/Visual/Joint_1.stl"/>
      </geometry>
    </collision>
    <inertial>
      <mass value="3.0"/>
      <origin rpy="0.0 0.0 0.0" xyz="0.11001 0.00000 0.01900"/>
      <inertia ixx="0.0032067608" ixy="0.0" ixz="0.0" iyy="0.0262497430" iyz="0.0" izz="0.0279990869"/>
    </inertial>
  </link>
  <!-- Configuration of the part called 'Joint 2'. -->
  <joint name="joint_2" type="revolute">
    <parent link="link_1"/>
    <child link="link_2"/>
    <origin rpy="0.0 0.0 0.0" xyz="0.22500 0.0 0.04990"/>
    <axis xyz="0 0 1"/>
    <limit effort="88.0" lower="-2.4434609413" upper="2.4434609413" velocity="6.28"/>
  </joint>
  <link name="link_2">
    <visual>
      <geometry>
        <mesh filename="/Mesh/Visual/Joint_2.stl"/>
      </geometry>
      <material name="Custom_Color">
        <color rgba="0.9 0.9 0.9 1.0"/>
      </material>
    </visual>
    <collision>
      <geometry>
        <mesh filename="/Mesh/Visual/Joint_2.stl"/>
      </geometry>
    </collision>
    <inertial>
      <mass value="4.5"/>
      <origin rpy="0.0 0.0 0.0" xyz="0.08931 0.00000 0.10894"/>
      <inertia ixx="0.0378616637" ixy="0.0" ixz="0.0" iyy="0.0582481368" iyz="0.0" izz="0.0331990963"/>
    </inertial>
  </link>
  <!-- Configuration of the part called 'Joint 3'. -->
  <joint name="joint_3" type="prismatic">
    <parent link="link_2"/>
    <child link="link_3"/>
    <origin rpy="-3.1415901184 0.0 0.0" xyz="0.17500 0.0 0.0"/>
    <axis xyz="0 0 -1"/>
    <limit effort="44.0" lower="0.0000000000" upper="0.1500000060" velocity="1.0"/>
  </joint>
  <link name="link_3">
    <visual>
      <geometry>
        <mesh filename="/Mesh/Visual/Joint_3.stl"/>
      </geometry>
      <material name="Custom_Color">
        <color rgba="0.9 0.9 0.9 1.0"/>
      </material>
    </visual>
    <collision>
      <geometry>
        <mesh filename="/Mesh/Visual/Joint_3.stl"/>
      </geometry>
    </collision>
    <inertial>
      <mass value="0.5"/>
      <origin rpy="0.0 0.0 0.0" xyz="0.00000 0.00000 0.00000"/>
      <inertia ixx="0.0000003332" ixy="0.0" ixz="0.0" iyy="0.0000003332" iyz="0.0" izz="0.0000003332"/>
    </inertial>
  </link>
  <!-- Configuration of the part called 'Joint 4'. -->
  <joint name="joint_4" type="revolute">
    <parent link="link_3"/>
    <child link="link_4"/>
    <origin rpy="0.0 0.0 0.0" xyz="0.0 0.0 0.07850"/>
    <axis xyz="0 0 1"/>
    <limit effort="22.0" lower="-3.1415927410" upper="3.1415927410" velocity="12.56"/>
  </joint>
  <link name="link_4">
    <visual>
      <geometry>
        <mesh filename="/Mesh/Visual/Joint_4.stl"/>
      </geometry>
      <material name="Custom_Color">
        <color rgba="0.9 0.9 0.9 1.0"/>
      </material>
    </visual>
    <collision>
      <geometry>
        <mesh filename="/Mesh/Visual/Joint_4.stl"/>
      </geometry>
    </collision>
    <inertial>
      <mass value="0.5"/>
      <origin rpy="0.0 0.0 0.0" xyz="-0.00001 0.00000 -0.16500"/>
      <inertia ixx="0.0045731454" ixy="0.0" ixz="0.0" iyy="0.0045731204" iyz="0.0" izz="0.0000748951"/>
    </inertial>
  </link>
  <!-- Configuration of the part called 'End-Effector (EE)'. -->
  <joint name="ee" type="fixed">
    <origin rpy="0.0 0.0 0.0" xyz="0.0 0.0 0.0"/>
    <parent link="link_4"/>
    <child link="ee_link"/>
  </joint>
  <link name="ee_link"/>
</robot>
