<?xml version="1.0"?>
<robot name="ABB_IRB_120_L_Ax">
  <!-- Configuration of the part called 'Base 0'. -->
  <link name="base_link">
    <visual>
      <geometry>
        <mesh filename="/Mesh/Visual/Base.stl"/>
      </geometry>
      <material name="Custom_Color">
        <color rgba="0.9 0.9 0.9 1.0"/>
      </material>
    </visual>
    <collision>
      <geometry>
        <mesh filename="/Mesh/Visual/Base.stl"/>
      </geometry>
    </collision>
    <inertial>
      <mass value="46.0"/>
      <origin rpy="0.0 0.0 0.0" xyz="-0.33848 -0.03402 0.05515"/>
      <inertia ixx="0.4389943236" ixy="0.0" ixz="0.0" iyy="5.4455057650" iyz="0.0" izz="5.7912640463"/>
    </inertial>
  </link>
  <!-- Configuration of the part called 'Joint L'. -->
  <joint name="joint_L" type="prismatic">
    <parent link="base_link"/>
    <child link="link_L"/>
    <origin rpy="0.0 0.0 0.0" xyz="0.0 0.0 0.11300"/>
    <axis xyz="-1 0 0"/>
    <limit effort="4.0" lower="0.0000000000" upper="0.8000000119" velocity="0.5"/>
  </joint>
  <link name="link_L">
    <visual>
      <geometry>
        <mesh filename="/Mesh/Visual/Joint_L.stl"/>
      </geometry>
      <material name="Custom_Color">
        <color rgba="0.9 0.9 0.9 1.0"/>
      </material>
    </visual>
    <collision>
      <geometry>
        <mesh filename="/Mesh/Visual/Joint_L.stl"/>
      </geometry>
    </collision>
    <inertial>
      <mass value="4.0"/>
      <origin rpy="0.0 0.0 0.0" xyz="0.00052 -0.03000 -0.01960"/>
      <inertia ixx="0.0197043276" ixy="0.0" ixz="0.0" iyy="0.0113076893" iyz="0.0" izz="0.0299880000"/>
    </inertial>
  </link>
  <!-- Configuration of the part called 'Base 1'. -->
  <joint name="base_1" type="fixed">
    <parent link="link_L"/>
    <child link="base_link_1"/>
    <origin rpy="0.0 0.0 0.0" xyz="0.0 0.0 0.0"/>
  </joint>
  <link name="base_link_1">
    <visual>
      <geometry>
        <mesh filename="/Mesh/Visual/Base_1.stl"/>
      </geometry>
      <material name="Custom_Color">
        <color rgba="0.9 0.9 0.9 1.0"/>
      </material>
    </visual>
    <collision>
      <geometry>
        <mesh filename="/Mesh/Visual/Base_1.stl"/>
      </geometry>
    </collision>
    <inertial>
      <mass value="8.25"/>
      <origin rpy="0.0 0.0 0.0" xyz="-0.06060 0.00000 0.08317"/>
      <inertia ixx="0.0414074620" ixy="0.0" ixz="0.0" iyy="0.0813585807" iyz="0.0" izz="0.0847409665"/>
    </inertial>
  </link>
  <!-- Configuration of the part called 'Joint 1'. -->
  <joint name="joint_1" type="revolute">
    <parent link="base_link_1"/>
    <child link="link_1"/>
    <origin rpy="0.0 0.0 0.0" xyz="0.0 0.0 0.29000"/>
    <axis xyz="0 0 1"/>
    <limit effort="2.0" lower="-2.8797931671" upper="2.8797931671" velocity="4.36"/>
  </joint>
  <link name="link_1">
    <visual>
      <geometry>
        <mesh filename="/Mesh/Visual/Joint_1.stl"/>
      </geometry>
      <material name="Custom_Color">
        <color rgba="0.9 0.9 0.9 1.0"/>
      </material>
    </visual>
    <collision>
      <geometry>
        <mesh filename="/Mesh/Visual/Joint_1.stl"/>
      </geometry>
    </collision>
    <inertial>
      <mass value="3.45"/>
      <origin rpy="0.0 0.0 0.0" xyz="0.00000 0.00000 -0.03631"/>
      <inertia ixx="0.0247288653" ixy="0.0" ixz="0.0" iyy="0.0244805660" iyz="0.0" izz="0.0268170434"/>
    </inertial>
  </link>
  <!-- Configuration of the part called 'Joint 2'. -->
  <joint name="joint_2" type="revolute">
    <parent link="link_1"/>
    <child link="link_2"/>
    <origin rpy="-1.5707999468 -1.5707999468 0.0" xyz="0.0 0.0 0.0"/>
    <axis xyz="0 0 1"/>
    <limit effort="2.0" lower="-1.9198621511" upper="1.9198621511" velocity="4.36"/>
  </joint>
  <link name="link_2">
    <visual>
      <geometry>
        <mesh filename="/Mesh/Visual/Joint_2.stl"/>
      </geometry>
      <material name="Custom_Color">
        <color rgba="0.9 0.9 0.9 1.0"/>
      </material>
    </visual>
    <collision>
      <geometry>
        <mesh filename="/Mesh/Visual/Joint_2.stl"/>
      </geometry>
    </collision>
    <inertial>
      <mass value="5.9"/>
      <origin rpy="0.0 0.0 0.0" xyz="0.12301 0.00000 -0.00025"/>
      <inertia ixx="0.0339406087" ixy="0.0" ixz="0.0" iyy="0.0981539755" iyz="0.0" izz="0.0848397920"/>
    </inertial>
  </link>
  <!-- Configuration of the part called 'Joint 3'. -->
  <joint name="joint_3" type="revolute">
    <parent link="link_2"/>
    <child link="link_3"/>
    <origin rpy="0.0 0.0 0.0" xyz="0.27000 0.0 0.0"/>
    <axis xyz="0 0 1"/>
    <limit effort="1.0" lower="-1.9198621511" upper="1.2217304707" velocity="4.36"/>
  </joint>
  <link name="link_3">
    <visual>
      <geometry>
        <mesh filename="/Mesh/Visual/Joint_3.stl"/>
      </geometry>
      <material name="Custom_Color">
        <color rgba="0.9 0.9 0.9 1.0"/>
      </material>
    </visual>
    <collision>
      <geometry>
        <mesh filename="/Mesh/Visual/Joint_3.stl"/>
      </geometry>
    </collision>
    <inertial>
      <mass value="2.95"/>
      <origin rpy="0.0 0.0 0.0" xyz="0.04557 0.03259 0.00175"/>
      <inertia ixx="0.0179094449" ixy="0.0" ixz="0.0" iyy="0.0119661969" iyz="0.0" izz="0.0233193087"/>
    </inertial>
  </link>
  <!-- Configuration of the part called 'Joint 4'. -->
  <joint name="joint_4" type="revolute">
    <parent link="link_3"/>
    <child link="link_4"/>
    <origin rpy="-1.5707999468 0.0 0.0" xyz="0.07000 0.30200 0.0"/>
    <axis xyz="0 0 1"/>
    <limit effort="0.5" lower="-2.7925267220" upper="2.7925267220" velocity="5.58"/>
  </joint>
  <link name="link_4">
    <visual>
      <geometry>
        <mesh filename="/Mesh/Visual/Joint_4.stl"/>
      </geometry>
      <material name="Custom_Color">
        <color rgba="0.9 0.9 0.9 1.0"/>
      </material>
    </visual>
    <collision>
      <geometry>
        <mesh filename="/Mesh/Visual/Joint_4.stl"/>
      </geometry>
    </collision>
    <inertial>
      <mass value="2.3"/>
      <origin rpy="0.0 0.0 0.0" xyz="0.00700 0.00047 -0.05666"/>
      <inertia ixx="0.0102593137" ixy="0.0" ixz="0.0" iyy="0.0093211292" iyz="0.0" izz="0.0052362872"/>
    </inertial>
  </link>
  <!-- Configuration of the part called 'Joint 5'. -->
  <joint name="joint_5" type="revolute">
    <parent link="link_4"/>
    <child link="link_5"/>
    <origin rpy="1.5707999468 0.0 0.0" xyz="0.0 0.0 0.0"/>
    <axis xyz="0 0 1"/>
    <limit effort="0.5" lower="-2.0943951607" upper="2.0943951607" velocity="5.58"/>
  </joint>
  <link name="link_5">
    <visual>
      <geometry>
        <mesh filename="/Mesh/Visual/Joint_5.stl"/>
      </geometry>
      <material name="Custom_Color">
        <color rgba="0.9 0.9 0.9 1.0"/>
      </material>
    </visual>
    <collision>
      <geometry>
        <mesh filename="/Mesh/Visual/Joint_5.stl"/>
      </geometry>
    </collision>
    <inertial>
      <mass value="1.55"/>
      <origin rpy="0.0 0.0 0.0" xyz="0.00000 0.00006 0.00000"/>
      <inertia ixx="0.0028717650" ixy="0.0" ixz="0.0" iyy="0.0014939825" iyz="0.0" izz="0.0031141211"/>
    </inertial>
  </link>
  <!-- Configuration of the part called 'Joint 6'. -->
  <joint name="joint_6" type="revolute">
    <parent link="link_5"/>
    <child link="link_6"/>
    <origin rpy="-1.5707999468 -3.1415901184 0.0" xyz="0.0 0.07200 0.0"/>
    <axis xyz="0 0 1"/>
    <limit effort="0.5" lower="-3.1415927410" upper="3.1415927410" velocity="7.33"/>
  </joint>
  <link name="link_6">
    <visual>
      <geometry>
        <mesh filename="/Mesh/Visual/Joint_6.stl"/>
      </geometry>
      <material name="Custom_Color">
        <color rgba="0.9 0.9 0.9 1.0"/>
      </material>
    </visual>
    <collision>
      <geometry>
        <mesh filename="/Mesh/Visual/Joint_6.stl"/>
      </geometry>
    </collision>
    <inertial>
      <mass value="0.6"/>
      <origin rpy="0.0 0.0 0.0" xyz="0.00000 0.00000 -0.00650"/>
      <inertia ixx="0.0000877363" ixy="0.0" ixz="0.0" iyy="0.0000884146" iyz="0.0" izz="0.0001592577"/>
    </inertial>
  </link>
  <!-- Configuration of the part called 'End-Effector (EE)'. -->
  <joint name="ee" type="fixed">
    <origin rpy="0.0 0.0 0.0" xyz="0.0 0.0 0.0"/>
    <parent link="link_6"/>
    <child link="ee_link"/>
  </joint>
  <link name="ee_link"/>
</robot>
