<?xml version="1.0" ?>
<robot name="SMC_LEFB25_14000">
  <!-- Configuration of the part called 'Base 0'. -->
  <link name="base_link">
    <visual>
      <geometry>
        <mesh filename="/Mesh/Visual/Base.stl"/>
      </geometry>
      <material name="Custom_Color">
        <color rgba="0.90 0.90 0.90 1.0"/>
      </material>
    </visual>
    <collision>
      <geometry>
        <mesh filename="/Mesh/Collision/Base.stl"/>
      </geometry>
    </collision>
    <inertial>
      <mass value="5.0"/>
      <origin rpy="0.0 0.0 0.0" xyz="0.00000 0.70200 0.08296"/>
      <inertia ixx="1.1631942010249054" ixy="0.0" ixz="0.0" iyy="0.019373868598281493" iyz="0.0" izz="1.1596340665447389"/>
    </inertial>
  </link>
  <!-- Configuration of the part called 'Joint L'. -->
  <joint name="joint_L" type="prismatic">
    <parent link="base_link"/>
    <child link="link_L"/>
    <origin rpy="0.0 0.0 0.0" xyz="0.0 0.0 0.168499"/>
    <axis xyz="0 1 0"/>
    <limit effort="1.0" lower="0.0" upper="1.4" velocity="2.0"/>
  </joint>
  <link name="link_L">
    <visual>
      <geometry>
        <mesh filename="/Mesh/Visual/Joint_L.stl"/>
      </geometry>
      <material name="Custom_Color">
        <color rgba="0.90 0.90 0.90 1.0"/>
      </material>
    </visual>
    <collision>
      <geometry>
        <mesh filename="/Mesh/Collision/Joint_L.stl"/>
      </geometry>
    </collision>
    <inertial>
      <mass value="0.5"/>
      <origin rpy="0.0 0.0 0.0" xyz="0.00000 0.00002 -0.00453"/>
      <inertia ixx="0.0004371018969552862" ixy="0.0" ixz="0.0" iyy="0.00010726118486012024" iyz="0.0" izz="0.0005375406112985208"/>
    </inertial>
  </link>
  <!-- Configuration of the part called 'Shuttle'. -->
  <joint name="shuttle" type="fixed">
    <parent link="link_L"/>
    <child link="link_shuttle"/>
    <origin rpy="0.0 0.0 0.0" xyz="0.0 0.0 0.0"/>
    <axis xyz="0 1 0"/>
    <limit effort="0.0" lower="0.0" upper="0.0" velocity="0.0"/>
  </joint>
  <link name="link_shuttle">
    <visual>
      <geometry>
        <mesh filename="/Mesh/Visual/Shuttle.stl"/>
      </geometry>
      <material name="Custom_Color">
        <color rgba="0.90 0.90 0.90 1.0"/>
      </material>
    </visual>
    <collision>
      <geometry>
        <mesh filename="/Mesh/Collision/Shuttle.stl"/>
      </geometry>
    </collision>
    <inertial>
      <mass value="0.25"/>
      <origin rpy="0.0 0.0 0.0" xyz="0.00022 0.00000 0.02508"/>
      <inertia ixx="0.0012454715769191728" ixy="0.0" ixz="0.0" iyy="0.0008013035875711556" iyz="0.0" izz="0.0019419846512886754"/>
    </inertial>
  </link>
  <!-- Configuration of the part called 'End-Effector (EE)'. -->
  <joint name="ee" type="fixed">
    <origin rpy="0.0 0.0 0.0" xyz="0.0 0.0 0.019998"/>
    <parent link="link_shuttle"/>
    <child link="ee_link"/>
  </joint>
  <link name="ee_link"/>
</robot>
